<?xml version="1.0" ?>
<!-- =================================================================================== -->
<!-- |    This document was autogenerated by xacro from redbot02.urdf.xacro            | -->
<!-- |    EDITING THIS FILE BY HAND IS NOT RECOMMENDED                                 | -->
<!-- =================================================================================== -->
<robot name="redbot02">
  <!-- Define materials -->
  <material name="red">
    <color rgba="1.0 0.1 0.1 1"/>
  </material>
  <material name="gray">
    <color rgba="0.3 0.3 0.3 1"/>
  </material>
  <material name="black">
    <color rgba="0.1 0.1 0.1 1"/>
  </material>
  <!-- Base footprint link -->
  <link name="base_footprint"/>
  <!-- Base link -->
  <link name="base_link">
    <visual>
      <origin xyz="-0.05 0 0.114"/>
      <geometry>
        <box size="0.60 0.30 0.240"/>
      </geometry>
      <material name="black"/>
    </visual>
  </link>
  <joint name="base_link_link_joint" type="fixed">
    <parent link="base_footprint"/>
    <child link="base_link"/>
    <origin xyz="0 0 0.114"/>
  </joint>
  <!-- Lidar link and joint -->
  <link name="lidar_scan">
    <visual>
      <origin xyz="0 0 0"/>
      <geometry>
        <mesh filename="package://redbot02_description/meshes/lidar.STL" scale="0.001 0.001 0.001"/>
      </geometry>
      <material name="gray"/>
    </visual>
    <collision>
      <origin rpy="0 0 0" xyz="0 0 0"/>
      <geometry>
        <mesh filename="package://redbot02_description/meshes/lidar.STL" scale="0.001 0.001 0.001"/>
      </geometry>
    </collision>
  </link>
  <joint name="laser_link_joint" type="fixed">
    <parent link="base_link"/>
    <child link="lidar_scan"/>
    <origin xyz="0.20 0 0.242"/>
  </joint>
  <!-- IMU link and joint -->
  <link name="imu_link"/>
  <joint name="imu_link_joint" type="fixed">
    <parent link="base_link"/>
    <child link="imu_link"/>
    <origin xyz="0.0 0.0 0.20"/>
  </joint>
  <link name="bracket_lidar_camera">
    <inertial>
      <origin rpy="0 0 0" xyz="5.65954616504882E-10 7.36872513007469E-09 -0.00280091247127531"/>
      <mass value="0.05"/>
      <inertia ixx="0.000180293267616765" ixy="3.49702912743621E-10" ixz="-5.96562390165147E-13" iyy="0.000180293249897517" iyz="-1.35611495762941E-11" izz="0.000340883721561127"/>
    </inertial>
    <visual>
      <origin rpy="1.57 -3.14 -1.57" xyz="0.0375 -0.0565 0.135"/>
      <geometry>
        <mesh filename="package://redbot02_description/meshes/bracket.STL" scale="0.001 0.001 0.001"/>
      </geometry>
      <material name="">
        <color rgba="0.792156862745098 0.819607843137255 0.933333333333333 1"/>
      </material>
    </visual>
    <collision>
      <origin rpy="0 0 0" xyz="0 0 0"/>
      <geometry>
        <mesh filename="package://redbot02_description/meshes/bracket.STL" scale="0.001 0.001 0.001"/>
      </geometry>
    </collision>
  </link>
  <joint name="bracket_link_joint" type="fixed">
    <parent link="base_link"/>
    <child link="bracket_lidar_camera"/>
    <origin xyz="0.20 0.0 0.186"/>
  </joint>
  <link name="wheel_left_link">
    <inertial>
      <origin rpy="0 0 0" xyz="5.65954616504882E-10 7.36872513007469E-09 -0.00280091247127531"/>
      <mass value="0.168927903786118"/>
      <inertia ixx="0.000180293267616765" ixy="3.49702912743621E-10" ixz="-5.96562390165147E-13" iyy="0.000180293249897517" iyz="-1.35611495762941E-11" izz="0.000340883721561127"/>
    </inertial>
    <visual>
      <origin rpy="0 0 0" xyz="0 0 0"/>
      <geometry>
        <cylinder length="0.074" radius="0.114"/>
      </geometry>
      <material name="">
        <color rgba="0.792156862745098 0.819607843137255 0.933333333333333 1"/>
      </material>
    </visual>
    <collision>
      <origin rpy="0 0 0" xyz="0 0 0"/>
      <geometry>
        <cylinder length="0.074" radius="0.114"/>
      </geometry>
    </collision>
  </link>
  <joint name="wheel_left_joint" type="continuous">
    <origin rpy="-1.5707963267949 0 0" xyz="0.00243065284555088 0.202000000002307 0.000100106132487177"/>
    <parent link="base_link"/>
    <child link="wheel_left_link"/>
    <axis xyz="0 0 1"/>
  </joint>
  <link name="wheel_right_link">
    <inertial>
      <origin rpy="0 0 0" xyz="5.65954616504882E-10 7.36872513007469E-09 -0.00280091247127531"/>
      <mass value="0.168927903786118"/>
      <inertia ixx="0.000180293267616765" ixy="3.49702912743621E-10" ixz="-5.96562390165147E-13" iyy="0.000180293249897517" iyz="-1.35611495762941E-11" izz="0.000340883721561127"/>
    </inertial>
    <visual>
      <origin rpy="0 0 0" xyz="0 0 0"/>
      <geometry>
        <cylinder length="0.074" radius="0.114"/>
      </geometry>
      <material name="">
        <color rgba="0.792156862745098 0.819607843137255 0.933333333333333 1"/>
      </material>
    </visual>
    <collision>
      <origin rpy="0 0 0" xyz="0 0 0"/>
      <geometry>
        <cylinder length="0.074" radius="0.114"/>
      </geometry>
    </collision>
  </link>
  <joint name="wheel_right_joint" type="continuous">
    <origin rpy="-1.5707963267949 0 0" xyz="0.000243065284555311 -0.20200000997693 0.000100106132487593"/>
    <parent link="base_link"/>
    <child link="wheel_right_link"/>
    <axis xyz="0 0 1"/>
  </joint>
  <!-- Caster back link and joint -->
  <link name="caster_back_link">
    <inertial>
      <origin rpy="0 0 0" xyz="0.00712939689443792 -0.0131605253570176 8.95324089172922E-09"/>
      <mass value="0.205322871078586"/>
      <inertia ixx="0.000181440969274869" ixy="3.79381726757464E-05" ixz="-4.39393075162352E-11" iyy="0.000117632047892804" iyz="2.10111827256733E-12" izz="0.000234531410256484"/>
    </inertial>
    <visual>
      <origin rpy="0 0 0" xyz="0 0 0"/>
      <geometry>
        <mesh filename="package://redbot02_description/meshes/caster_back_link.STL" scale="1.25 1.25 1.25"/>
      </geometry>
      <material name="">
        <color rgba="0.792156862745098 0.819607843137255 0.933333333333333 1"/>
      </material>
    </visual>
    <collision>
      <origin rpy="0 0 0" xyz="0 0 0"/>
      <geometry>
        <mesh filename="package://redbot02_description/meshes/caster_back_link.STL" scale="1.25 1.25 1.25"/>
      </geometry>
    </collision>
  </link>
  <joint name="caster_back_joint" type="fixed">
    <origin rpy="-1.5707963267949 0 0" xyz="-0.190006195960553 0 -0.070614324940508"/>
    <parent link="base_link"/>
    <child link="caster_back_link"/>
    <axis xyz="0 0 0"/>
  </joint>
  <material name="aluminum">
    <color rgba="0.5 0.5 0.5 1"/>
  </material>
  <material name="plastic">
    <color rgba="0.1 0.1 0.1 1"/>
  </material>
  <!-- camera body, with origin at bottom screw mount -->
  <joint name="camera_joint" type="fixed">
    <origin rpy="0 0 0" xyz="0.195 0 0.292"/>
    <parent link="base_link"/>
    <child link="camera_bottom_screw_frame"/>
  </joint>
  <link name="camera_bottom_screw_frame"/>
  <joint name="camera_link_joint" type="fixed">
    <origin rpy="0 0 0" xyz="0.011150000000000002 0.0475 0.0145"/>
    <parent link="camera_bottom_screw_frame"/>
    <child link="camera_link"/>
  </joint>
  <link name="camera_link">
    <visual>
      <!-- the mesh origin is at front plate in between the two infrared camera axes -->
      <!-- <origin xyz="${d455_zero_depth_to_glass-d455_cam_depth/2} ${-d455_cam_depth_py} 0" rpy="0 0 0"/> -->
      <origin rpy="1.5707963267948966 0 1.5707963267948966" xyz="0.0046500000000000005 -0.0475 0"/>
      <geometry>
        <!-- <box size="${d455_cam_depth} ${d455_cam_width} ${d455_cam_height}"/> -->
        <mesh filename="package://redbot02_description/meshes/d455.stl" scale="0.001 0.001 0.001"/>
      </geometry>
      <material name="aluminum"/>
    </visual>
    <collision>
      <origin rpy="0 0 0" xyz="-0.00845 -0.0475 0"/>
      <geometry>
        <box size="0.026 0.124 0.029"/>
      </geometry>
    </collision>
    <inertial>
      <!-- The following are not reliable values, and should not be used for modeling -->
      <mass value="0.072"/>
      <origin xyz="0 0 0"/>
      <inertia ixx="0.003881243" ixy="0.0" ixz="0.0" iyy="0.000498940" iyz="0.0" izz="0.003879257"/>
    </inertial>
  </link>
  <!-- camera depth joints and links -->
  <joint name="camera_depth_joint" type="fixed">
    <origin rpy="0 0 0" xyz="0 0 0"/>
    <parent link="camera_link"/>
    <child link="camera_depth_frame"/>
  </joint>
  <link name="camera_depth_frame"/>
  <joint name="camera_depth_optical_joint" type="fixed">
    <origin rpy="-1.5707963267948966 0 -1.5707963267948966" xyz="0 0 0"/>
    <parent link="camera_depth_frame"/>
    <child link="camera_depth_optical_frame"/>
  </joint>
  <link name="camera_depth_optical_frame"/>
  <!-- camera left IR joints and links -->
  <joint name="camera_infra1_joint" type="fixed">
    <origin rpy="0 0 0" xyz="0 0.0 0"/>
    <parent link="camera_link"/>
    <child link="camera_infra1_frame"/>
  </joint>
  <link name="camera_infra1_frame"/>
  <joint name="camera_infra1_optical_joint" type="fixed">
    <origin rpy="-1.5707963267948966 0 -1.5707963267948966" xyz="0 0 0"/>
    <parent link="camera_infra1_frame"/>
    <child link="camera_infra1_optical_frame"/>
  </joint>
  <link name="camera_infra1_optical_frame"/>
  <!-- camera right IR joints and links -->
  <joint name="camera_infra2_joint" type="fixed">
    <origin rpy="0 0 0" xyz="0 -0.095 0"/>
    <parent link="camera_link"/>
    <child link="camera_infra2_frame"/>
  </joint>
  <link name="camera_infra2_frame"/>
  <joint name="camera_infra2_optical_joint" type="fixed">
    <origin rpy="-1.5707963267948966 0 -1.5707963267948966" xyz="0 0 0"/>
    <parent link="camera_infra2_frame"/>
    <child link="camera_infra2_optical_frame"/>
  </joint>
  <link name="camera_infra2_optical_frame"/>
  <!-- camera color joints and links -->
  <joint name="camera_color_joint" type="fixed">
    <origin rpy="0 0 0" xyz="0 -0.059 0"/>
    <parent link="camera_link"/>
    <child link="camera_color_frame"/>
  </joint>
  <link name="camera_color_frame"/>
  <joint name="camera_color_optical_joint" type="fixed">
    <origin rpy="-1.5707963267948966 0 -1.5707963267948966" xyz="0 0 0"/>
    <parent link="camera_color_frame"/>
    <child link="camera_color_optical_frame"/>
  </joint>
  <link name="camera_color_optical_frame"/>
  <link name="camera_accel_frame"/>
  <link name="camera_accel_optical_frame"/>
  <link name="camera_gyro_frame"/>
  <link name="camera_gyro_optical_frame"/>
  <link name="camera_imu_optical_frame"/>
  <joint name="camera_accel_joint" type="fixed">
    <origin rpy="0 0 0" xyz="-0.01602 -0.03022 0.0074"/>
    <parent link="camera_link"/>
    <child link="camera_accel_frame"/>
  </joint>
  <joint name="camera_accel_optical_joint" type="fixed">
    <origin rpy="-1.5707963267948966 0 -1.5707963267948966" xyz="0 0 0"/>
    <parent link="camera_accel_frame"/>
    <child link="camera_accel_optical_frame"/>
  </joint>
  <joint name="camera_gyro_joint" type="fixed">
    <origin rpy="0 0 0" xyz="-0.01602 -0.03022 0.0074"/>
    <parent link="camera_link"/>
    <child link="camera_gyro_frame"/>
  </joint>
  <joint name="camera_gyro_optical_joint" type="fixed">
    <origin rpy="-1.5707963267948966 0 -1.5707963267948966" xyz="0 0 0"/>
    <parent link="camera_gyro_frame"/>
    <child link="camera_gyro_optical_frame"/>
  </joint>
  <joint name="camera_imu_optical_joint" type="fixed">
    <origin rpy="0 0 0" xyz="0 0 0"/>
    <parent link="camera_gyro_optical_frame"/>
    <child link="camera_imu_optical_frame"/>
  </joint>
</robot>
